Exception in thread Thread-2:
Traceback (most recent call last):
  File "/data/users2/washbee/anaconda3/envs/neurips/lib/python3.8/threading.py", line 932, in _bootstrap_inner
